[0m11:19:46.173379 [debug] [MainThread]: Sending event: {'category': 'dbt', 'action': 'invocation', 'label': 'start', 'context': [<snowplow_tracker.self_describing_json.SelfDescribingJson object at 0x0000022964A47770>, <snowplow_tracker.self_describing_json.SelfDescribingJson object at 0x000002296289D590>, <snowplow_tracker.self_describing_json.SelfDescribingJson object at 0x000002296272F110>]}


============================== 11:19:46.177259 | c5ce0cb8-be15-4d17-8bf5-1c7cd3b8b904 ==============================
[0m11:19:46.177259 [info ] [MainThread]: Running with dbt=1.9.0
[0m11:19:46.177913 [debug] [MainThread]: running dbt with arguments {'printer_width': '80', 'indirect_selection': 'eager', 'log_cache_events': 'False', 'write_json': 'True', 'partial_parse': 'True', 'cache_selected_only': 'False', 'warn_error': 'None', 'version_check': 'True', 'debug': 'False', 'log_path': 'logs', 'profiles_dir': 'C:\\Users\\watra\\.dbt', 'fail_fast': 'False', 'use_colors': 'True', 'use_experimental_parser': 'False', 'no_print': 'None', 'quiet': 'False', 'empty': 'False', 'warn_error_options': 'WarnErrorOptions(include=[], exclude=[])', 'static_parser': 'True', 'introspect': 'True', 'invocation_command': 'dbt run --models staging.original_headline', 'target_path': 'None', 'log_format': 'default', 'send_anonymous_usage_stats': 'True'}
[0m11:19:46.178622 [error] [MainThread]: Encountered an error:
Runtime Error
  No dbt_project.yml found at expected path D:\education\ai_developer\ai2_data_engineering_opa24\dbt_project.yml
  Verify that each entry within packages.yml (and their transitive dependencies) contains a file named dbt_project.yml
  
[0m11:19:46.179716 [debug] [MainThread]: Command `dbt run` failed at 11:19:46.179608 after 0.34 seconds
[0m11:19:46.180046 [debug] [MainThread]: Sending event: {'category': 'dbt', 'action': 'invocation', 'label': 'end', 'context': [<snowplow_tracker.self_describing_json.SelfDescribingJson object at 0x0000022965AC8050>, <snowplow_tracker.self_describing_json.SelfDescribingJson object at 0x00000229658BB1D0>, <snowplow_tracker.self_describing_json.SelfDescribingJson object at 0x00000229659C5AE0>]}
[0m11:19:46.180389 [debug] [MainThread]: Flushing usage events
[0m11:19:46.673272 [debug] [MainThread]: An error was encountered while trying to flush usage events
[0m00:09:00.361015 [debug] [MainThread]: Sending event: {'category': 'dbt', 'action': 'invocation', 'label': 'start', 'context': [<snowplow_tracker.self_describing_json.SelfDescribingJson object at 0x000001E9507FF620>, <snowplow_tracker.self_describing_json.SelfDescribingJson object at 0x000001E94E6B96D0>, <snowplow_tracker.self_describing_json.SelfDescribingJson object at 0x000001E95138CCD0>]}


============================== 00:09:00.370930 | c3df96b6-1688-4bfb-885b-9c51b073a27a ==============================
[0m00:09:00.370930 [info ] [MainThread]: Running with dbt=1.9.0
[0m00:09:00.371550 [debug] [MainThread]: running dbt with arguments {'printer_width': '80', 'indirect_selection': 'eager', 'write_json': 'True', 'log_cache_events': 'False', 'partial_parse': 'True', 'cache_selected_only': 'False', 'warn_error': 'None', 'debug': 'False', 'profiles_dir': 'C:\\Users\\watra\\.dbt', 'log_path': 'logs', 'version_check': 'True', 'fail_fast': 'False', 'use_colors': 'True', 'use_experimental_parser': 'False', 'empty': 'None', 'quiet': 'False', 'no_print': 'None', 'warn_error_options': 'WarnErrorOptions(include=[], exclude=[])', 'static_parser': 'True', 'invocation_command': 'dbt ', 'introspect': 'True', 'target_path': 'None', 'log_format': 'default', 'send_anonymous_usage_stats': 'True'}
[0m00:09:00.372455 [error] [MainThread]: Encountered an error:
Runtime Error
  dbt_project.yml does not parse to a dictionary
[0m00:09:00.373653 [debug] [MainThread]: Command `cli deps` failed at 00:09:00.373514 after 0.70 seconds
[0m00:09:00.374038 [debug] [MainThread]: Sending event: {'category': 'dbt', 'action': 'invocation', 'label': 'end', 'context': [<snowplow_tracker.self_describing_json.SelfDescribingJson object at 0x000001E9516CFE10>, <snowplow_tracker.self_describing_json.SelfDescribingJson object at 0x000001E9516971D0>, <snowplow_tracker.self_describing_json.SelfDescribingJson object at 0x000001E9518097B0>]}
[0m00:09:00.374448 [debug] [MainThread]: Flushing usage events
[0m00:09:00.884010 [debug] [MainThread]: An error was encountered while trying to flush usage events
[0m00:58:14.219114 [debug] [MainThread]: Sending event: {'category': 'dbt', 'action': 'invocation', 'label': 'start', 'context': [<snowplow_tracker.self_describing_json.SelfDescribingJson object at 0x000002727A773620>, <snowplow_tracker.self_describing_json.SelfDescribingJson object at 0x00000272786496D0>, <snowplow_tracker.self_describing_json.SelfDescribingJson object at 0x000002727B2FCCD0>]}


============================== 00:58:14.230283 | 742d314a-c89a-40bd-ba5e-02fb8d58bf91 ==============================
[0m00:58:14.230283 [info ] [MainThread]: Running with dbt=1.9.0
[0m00:58:14.231143 [debug] [MainThread]: running dbt with arguments {'printer_width': '80', 'indirect_selection': 'eager', 'log_cache_events': 'False', 'write_json': 'True', 'partial_parse': 'True', 'cache_selected_only': 'False', 'profiles_dir': 'C:\\Users\\watra\\.dbt', 'version_check': 'True', 'fail_fast': 'False', 'log_path': 'logs', 'debug': 'False', 'warn_error': 'None', 'use_colors': 'True', 'use_experimental_parser': 'False', 'empty': 'None', 'quiet': 'False', 'no_print': 'None', 'log_format': 'default', 'invocation_command': 'dbt ', 'introspect': 'True', 'static_parser': 'True', 'target_path': 'None', 'warn_error_options': 'WarnErrorOptions(include=[], exclude=[])', 'send_anonymous_usage_stats': 'True'}
[0m00:58:14.232262 [error] [MainThread]: Encountered an error:
Runtime Error
  No dbt_project.yml found at expected path d:\education\ai_developer\ai2_data_engineering_opa24\7_dbt_modeling\dbt_code\dbt_packages\dbt-utils-1.3.0\dbt_project.yml
  Verify that each entry within packages.yml (and their transitive dependencies) contains a file named dbt_project.yml
  
[0m00:58:14.233498 [debug] [MainThread]: Command `cli deps` failed at 00:58:14.233292 after 0.34 seconds
[0m00:58:14.233908 [debug] [MainThread]: Sending event: {'category': 'dbt', 'action': 'invocation', 'label': 'end', 'context': [<snowplow_tracker.self_describing_json.SelfDescribingJson object at 0x000002727B63FE10>, <snowplow_tracker.self_describing_json.SelfDescribingJson object at 0x000002727B6071D0>, <snowplow_tracker.self_describing_json.SelfDescribingJson object at 0x000002727B7857B0>]}
[0m00:58:14.234279 [debug] [MainThread]: Flushing usage events
[0m00:58:14.700167 [debug] [MainThread]: An error was encountered while trying to flush usage events
[0m00:58:16.324417 [debug] [MainThread]: Sending event: {'category': 'dbt', 'action': 'invocation', 'label': 'start', 'context': [<snowplow_tracker.self_describing_json.SelfDescribingJson object at 0x0000013DD9BA3620>, <snowplow_tracker.self_describing_json.SelfDescribingJson object at 0x0000013DD7A796D0>, <snowplow_tracker.self_describing_json.SelfDescribingJson object at 0x0000013DDA71CCD0>]}


============================== 00:58:16.328106 | 3c325517-695a-4b57-989e-1542e5fb5517 ==============================
[0m00:58:16.328106 [info ] [MainThread]: Running with dbt=1.9.0
[0m00:58:16.328609 [debug] [MainThread]: running dbt with arguments {'printer_width': '80', 'indirect_selection': 'eager', 'write_json': 'True', 'log_cache_events': 'False', 'partial_parse': 'True', 'cache_selected_only': 'False', 'warn_error': 'None', 'fail_fast': 'False', 'debug': 'False', 'log_path': 'logs', 'profiles_dir': 'C:\\Users\\watra\\.dbt', 'version_check': 'True', 'use_colors': 'True', 'use_experimental_parser': 'False', 'empty': 'None', 'quiet': 'False', 'no_print': 'None', 'warn_error_options': 'WarnErrorOptions(include=[], exclude=[])', 'invocation_command': 'dbt ', 'introspect': 'True', 'static_parser': 'True', 'target_path': 'None', 'log_format': 'default', 'send_anonymous_usage_stats': 'True'}
[0m00:58:16.329169 [error] [MainThread]: Encountered an error:
Runtime Error
  No dbt_project.yml found at expected path d:\education\ai_developer\ai2_data_engineering_opa24\7_dbt_modeling\dbt_code\dbt_packages\dbt-utils-1.3.0\dbt_project.yml
  Verify that each entry within packages.yml (and their transitive dependencies) contains a file named dbt_project.yml
  
[0m00:58:16.330229 [debug] [MainThread]: Command `cli deps` failed at 00:58:16.330118 after 0.30 seconds
[0m00:58:16.330558 [debug] [MainThread]: Sending event: {'category': 'dbt', 'action': 'invocation', 'label': 'end', 'context': [<snowplow_tracker.self_describing_json.SelfDescribingJson object at 0x0000013DDAA5FE10>, <snowplow_tracker.self_describing_json.SelfDescribingJson object at 0x0000013DDAA271D0>, <snowplow_tracker.self_describing_json.SelfDescribingJson object at 0x0000013DDABA17B0>]}
[0m00:58:16.330905 [debug] [MainThread]: Flushing usage events
[0m00:58:16.815259 [debug] [MainThread]: An error was encountered while trying to flush usage events
